Workbook
Name Slicer_Department: #N/A
Name Slicer_Education_Label: #N/A
Name Slicer_OverTime: #N/A

Sheet Read_Me
A1: HR Employee Attrition Analysis
A3: Excel Data Analyst Portfolio Project
A5: 1. PROJECT OVERVIEW
A7: This project analyzes the IBM HR Employee Attrition dataset using Microsoft Excel. The purpose is to investigate patterns associated with employee attrition and explore how employee departures vary across departments, job roles, income, education, overtime, job satisfaction, work-life balance, distance from home, and length of service.
A9: The project demonstrates an end-to-end Excel data analysis workflow, including data preparation, data quality validation, formula-based calculations, exploratory data analysis, PivotTables, PivotCharts, slicers, dashboard development, and business recommendations.
A11: The dataset is fictional and was created by IBM data scientists for analytics practice.
A13: 2. BUSINESS PROBLEM
A15: Employee attrition can affect organizational stability, recruitment costs, productivity, and employee morale. HR stakeholders need to understand where employee departures are concentrated and which employee or workplace characteristics are associated with differences in attrition rates.
A17: The goal of this project is to transform employee-level data into understandable summaries and visualizations that help stakeholders investigate retention patterns.
A19: This analysis is descriptive. It identifies associations in the dataset and does not establish that any particular factor causes an employee to leave.
A21: 3. PROJECT OBJECTIVES
A23: 1. Calculate the total number of employees, the number who left, the number who stayed, and the overall attrition rate.
... A289: The final deliverable should be understandable to a recruiter, hiring manager, or business stakeholder without requiring them to inspect every individual employee record.

Sheet Dashboard
A1: HR ATTRITION DASHBOARD
A2: IBM fictional HR dataset | Explore attrition patterns; use the detailed tables and PivotTables for deeper analysis.
C5: TOTAL EMPLOYEES | D5: EMPLOYEES WHO LEFT | E5: OVERALL ATTRITION RATE | F5: AVERAGE MONTHLY INCOME
C6: =KPI_Summary!B4 -> 1470 | D6: =KPI_Summary!B5 -> 237 | E6: =KPI_Summary!B7 -> 0.16122449 | F6: =KPI_Summary!B8 -> 6502.9313

Sheet Raw_Data
A1: Age | B1: Attrition | C1: BusinessTravel | D1: DailyRate | E1: Department | F1: DistanceFromHome | G1: Education | H1: EducationField | I1: EmployeeCount | J1: EmployeeNumber | K1: EnvironmentSatisfaction | L1: Gender | M1: HourlyRate | N1: JobInvolvement | O1: JobLevel | P1: JobRole | Q1: JobSatisfaction | R1: MaritalStatus | S1: MonthlyIncome | T1: MonthlyRate | U1: NumCompaniesWorked | V1: Over18 | W1: OverTime | X1: PercentSalaryHike | Y1: PerformanceRating | Z1: RelationshipSatisfaction | AA1: StandardHours | AB1: StockOptionLevel | AC1: TotalWorkingYears | AD1: TrainingTimesLastYear | AE1: WorkLifeBalance | AF1: YearsAtCompany | AG1: YearsInCurrentRole | AH1: YearsSinceLastPromotion | AI1: YearsWithCurrManager
A2: 41 | B2: Yes | C2: Travel_Rarely | D2: 1102 | E2: Sales | F2: 1 | G2: 2 | H2: Life Sciences | I2: 1 | J2: 1 | K2: 2 | L2: Female | M2: 94 | N2: 3 | O2: 2 | P2: Sales Executive | Q2: 4 | R2: Single | S2: 5993 | T2: 19479 | U2: 8 | V2: Y | W2: Yes | X2: 11 | Y2: 3 | Z2: 1 | AA2: 80 | AB2: 0 | AC2: 8 | AD2: 0 | AE2: 1 | AF2: 6 | AG2: 4 | AH2: 0 | AI2: 5
A3: 49 | B3: No | C3: Travel_Frequently | D3: 279 | E3: Research & Development | F3: 8 | G3: 1 | H3: Life Sciences | I3: 1 | J3: 2 | K3: 3 | L3: Male | M3: 61 | N3: 2 | O3: 2 | P3: Research Scientist | Q3: 2 | R3: Married | S3: 5130 | T3: 24907 | U3: 1 | V3: Y | W3: No | X3: 23 | Y3: 4 | Z3: 4 | AA3: 80 | AB3: 1 | AC3: 10 | AD3: 3 | AE3: 3 | AF3: 10 | AG3: 7 | AH3: 1 | AI3: 7
A4: 37 | B4: Yes | C4: Travel_Rarely | D4: 1373 | E4: Research & Development | F4: 2 | G4: 2 | H4: Other | I4: 1 | J4: 4 | K4: 4 | L4: Male | M4: 92 | N4: 2 | O4: 1 | P4: Laboratory Technician | Q4: 3 | R4: Single | S4: 2090 | T4: 2396 | U4: 6 | V4: Y | W4: Yes | X4: 15 | Y4: 3 | Z4: 2 | AA4: 80 | AB4: 0 | AC4: 7 | AD4: 3 | AE4: 3 | AF4: 0 | AG4: 0 | AH4: 0 | AI4: 0
A5: 33 | B5: No | C5: Travel_Frequently | D5: 1392 | E5: Research & Development | F5: 3 | G5: 4 | H5: Life Sciences | I5: 1 | J5: 5 | K5: 4 | L5: Female | M5: 56 | N5: 3 | O5: 1 | P5: Research Scientist | Q5: 3 | R5: Married | S5: 2909 | T5: 23159 | U5: 1 | V5: Y | W5: Yes | X5: 11 | Y5: 3 | Z5: 3 | AA5: 80 | AB5: 0 | AC5: 8 | AD5: 3 | AE5: 3 | AF5: 8 | AG5: 7 | AH5: 3 | AI5: 0
A6: 27 | B6: No | C6: Travel_Rarely | D6: 591 | E6: Research & Development | F6: 2 | G6: 1 | H6: Medical | I6: 1 | J6: 7 | K6: 1 | L6: Male | M6: 40 | N6: 3 | O6: 1 | P6: Laboratory Technician | Q6: 2 | R6: Married | S6: 3468 | T6: 16632 | U6: 9 | V6: Y | W6: No | X6: 12 | Y6: 3 | Z6: 4 | AA6: 80 | AB6: 1 | AC6: 6 | AD6: 3 | AE6: 3 | AF6: 2 | AG6: 2 | AH6: 2 | AI6: 2
A7: 32 | B7: No | C7: Travel_Frequently | D7: 1005 | E7: Research & Development | F7: 2 | G7: 2 | H7: Life Sciences | I7: 1 | J7: 8 | K7: 4 | L7: Male | M7: 79 | N7: 3 | O7: 1 | P7: Laboratory Technician | Q7: 4 | R7: Single | S7: 3068 | T7: 11864 | U7: 0 | V7: Y | W7: No | X7: 13 | Y7: 3 | Z7: 3 | AA7: 80 | AB7: 0 | AC7: 8 | AD7: 2 | AE7: 2 | AF7: 7 | AG7: 7 | AH7: 3 | AI7: 6
A8: 59 | B8: No | C8: Travel_Rarely | D8: 1324 | E8: Research & Development | F8: 3 | G8: 3 | H8: Medical | I8: 1 | J8: 10 | K8: 3 | L8: Female | M8: 81 | N8: 4 | O8: 1 | P8: Laboratory Technician | Q8: 1 | R8: Married | S8: 2670 | T8: 9964 | U8: 4 | V8: Y | W8: Yes | X8: 20 | Y8: 4 | Z8: 1 | AA8: 80 | AB8: 3 | AC8: 12 | AD8: 3 | AE8: 2 | AF8: 1 | AG8: 0 | AH8: 0 | AI8: 0
A9: 30 | B9: No | C9: Travel_Rarely | D9: 1358 | E9: Research & Development | F9: 24 | G9: 1 | H9: Life Sciences | I9: 1 | J9: 11 | K9: 4 | L9: Male | M9: 67 | N9: 3 | O9: 1 | P9: Laboratory Technician | Q9: 3 | R9: Divorced | S9: 2693 | T9: 13335 | U9: 1 | V9: Y | W9: No | X9: 22 | Y9: 4 | Z9: 2 | AA9: 80 | AB9: 1 | AC9: 1 | AD9: 2 | AE9: 3 | AF9: 1 | AG9: 0 | AH9: 0 | AI9: 0
A10: 38 | B10: No | C10: Travel_Frequently | D10: 216 | E10: Research & Development | F10: 23 | G10: 3 | H10: Life Sciences | I10: 1 | J10: 12 | K10: 4 | L10: Male | M10: 44 | N10: 2 | O10: 3 | P10: Manufacturing Director | Q10: 3 | R10: Single | S10: 9526 | T10: 8787 | U10: 0 | V10: Y | W10: No | X10: 21 | Y10: 4 | Z10: 2 | AA10: 80 | AB10: 0 | AC10: 10 | AD10: 2 | AE10: 3 | AF10: 9 | AG10: 7 | AH10: 1 | AI10: 8
A11: 36 | B11: No | C11: Travel_Rarely | D11: 1299 | E11: Research & Development | F11: 27 | G11: 3 | H11: Medical | I11: 1 | J11: 13 | K11: 3 | L11: Male | M11: 94 | N11: 3 | O11: 2 | P11: Healthcare Representative | Q11: 3 | R11: Married | S11: 5237 | T11: 16577 | U11: 6 | V11: Y | W11: No | X11: 13 | Y11: 3 | Z11: 2 | AA11: 80 | AB11: 2 | AC11: 17 | AD11: 3 | AE11: 2 | AF11: 7 | AG11: 7 | AH11: 7 | AI11: 7
A12: 35 | B12: No | C12: Travel_Rarely | D12: 809 | E12: Research & Development | F12: 16 | G12: 3 | H12: Medical | I12: 1 | J12: 14 | K12: 1 | L12: Male | M12: 84 | N12: 4 | O12: 1 | P12: Laboratory Technician | Q12: 2 | R12: Married | S12: 2426 | T12: 16479 | U12: 0 | V12: Y | W12: No | X12: 13 | Y12: 3 | Z12: 3 | AA12: 80 | AB12: 1 | AC12: 6 | AD12: 5 | AE12: 3 | AF12: 5 | AG12: 4 | AH12: 0 | AI12: 3
A13: 29 | B13: No | C13: Travel_Rarely | D13: 153 | E13: Research & Development | F13: 15 | G13: 2 | H13: Life Sciences | I13: 1 | J13: 15 | K13: 4 | L13: Female | M13: 49 | N13: 2 | O13: 2 | P13: Laboratory Technician | Q13: 3 | R13: Single | S13: 4193 | T13: 12682 | U13: 0 | V13: Y | W13: Yes | X13: 12 | Y13: 3 | Z13: 4 | AA13: 80 | AB13: 0 | AC13: 10 | AD13: 3 | AE13: 3 | AF13: 9 | AG13: 5 | AH13: 0 | AI13: 8
... A1471: 34 | B1471: No | C1471: Travel_Rarely | D1471: 628 | E1471: Research & Development | F1471: 8 | G1471: 3 | H1471: Medical | I1471: 1 | J1471: 2068 | K1471: 2 | L1471: Male | M1471: 82 | N1471: 4 | O1471: 2 | P1471: Laboratory Technician | Q1471: 3 | R1471: Married | S1471: 4404 | T1471: 10228 | U1471: 2 | V1471: Y | W1471: No | X1471: 12 | Y1471: 3 | Z1471: 1 | AA1471: 80 | AB1471: 0 | AC1471: 6 | AD1471: 3 | AE1471: 4 | AF1471: 4 | AG1471: 3 | AH1471: 1 | AI1471: 2

Sheet Cleaned_Data
A1: Age | B1: Attrition | C1: BusinessTravel | D1: DailyRate | E1: Department | F1: DistanceFromHome | G1: Education | H1: EducationField | I1: EmployeeCount | J1: EmployeeNumber | K1: EnvironmentSatisfaction | L1: Gender | M1: HourlyRate | N1: JobInvolvement | O1: JobLevel | P1: JobRole | Q1: JobSatisfaction | R1: MaritalStatus | S1: MonthlyIncome | T1: MonthlyRate | U1: NumCompaniesWorked | V1: Over18 | W1: OverTime | X1: PercentSalaryHike | Y1: PerformanceRating | Z1: RelationshipSatisfaction | AA1: StandardHours | AB1: StockOptionLevel | AC1: TotalWorkingYears | AD1: TrainingTimesLastYear | AE1: WorkLifeBalance | AF1: YearsAtCompany | AG1: YearsInCurrentRole | AH1: YearsSinceLastPromotion | AI1: YearsWithCurrManager | AJ1: Education_Label | AK1: EnvironmentSatisfaction_Label | AL1: JobInvolvement_Label | AM1: JobSatisfaction_Label | AN1: PerformanceRating_Label | AO1: WorkLifeBalance_Label | AP1: Attrition_Flag | AQ1: Income_Band | AR1: Distance_Band | AS1: Tenure_Board
A2: 41 | B2: Yes | C2: Travel_Rarely | D2: 1102 | E2: Sales | F2: 1 | G2: 2 | H2: Life Sciences | I2: 1 | J2: 1 | K2: 2 | L2: Female | M2: 94 | N2: 3 | O2: 2 | P2: Sales Executive | Q2: 4 | R2: Single | S2: 5993 | T2: 19479 | U2: 8 | V2: Y | W2: Yes | X2: 11 | Y2: 3 | Z2: 1 | AA2: 80 | AB2: 0 | AC2: 8 | AD2: 0 | AE2: 1 | AF2: 6 | AG2: 4 | AH2: 0 | AI2: 5 | AJ2: {=_xlfn.SWITCH(CleanEmployeeData[[#This Row],[Education]],1,"Below College",2,"College",3,"Bachelor",4,"Master",5,"Doctor","Unknown")} -> College | AK2: {=_xlfn.SWITCH(CleanEmployeeData[[#This Row],[EnvironmentSatisfaction]],1,"Low",2,"Medium",3,"High",4,"Very High","Unknown")} -> Medium | AL2: {=_xlfn.SWITCH(CleanEmployeeData[[#This Row],[JobInvolvement]],1,"Low",2,"Medium",3,"High",4,"Very High","Unknown")} -> High | AM2: {=_xlfn.SWITCH(CleanEmployeeData[[#This Row],[JobSatisfaction]],1,"Low",2,"Medium",3,"High",4,"Very High","Unknown")} -> Very High | AN2: {=_xlfn.SWITCH(CleanEmployeeData[[#This Row],[PerformanceRating]],1,"Low",2,"Good",3,"Excellent",4,"Outstanding","Unknown")} -> Excellent | AO2: {=_xlfn.SWITCH(CleanEmployeeData[[#This Row],[WorkLifeBalance]],1,"Bad",2,"Good",3,"Better",4,"Best","Unknown")} -> Bad | AP2: =IF(CleanEmployeeData[[#This Row],[Attrition]]="Yes",1,IF(CleanEmployeeData[[#This Row],[Attrition]]="No",0,"")) -> 1 | AQ2: {=_xlfn.IFS(CleanEmployeeData[[#This Row],[MonthlyIncome]]<=3000,"0–3,000",CleanEmployeeData[[#This Row],[MonthlyIncome]]<=6000,"3,001–6,000",CleanEmployeeData[[#This Row],[MonthlyIncome]]<=10000,"6,001–10,000",TRUE,"10,001+")} -> 3,001–6,000 | AR2: {=_xlfn.IFS(CleanEmployeeData[[#This Row],[DistanceFromHome]]<=5,"0–5 miles",CleanEmployeeData[[#This Row],[DistanceFromHome]]<=10,"6–10 miles",CleanEmployeeData[[#This Row],[DistanceFromHome]]<=15,"11–15 miles",TRUE,"16+ miles")} -> 0–5 miles | AS2: {=_xlfn.IFS(CleanEmployeeData[[#This Row],[YearsAtCompany]]<=1,"0–1 years",CleanEmployeeData[[#This Row],[YearsAtCompany]]<=5,"2–5 years",CleanEmployeeData[[#This Row],[YearsAtCompany]]<=10,"6–10 years",TRUE,"11+ years")} -> 6–10 years
A3: 49 | B3: No | C3: Travel_Frequently | D3: 279 | E3: Research & Development | F3: 8 | G3: 1 | H3: Life Sciences | I3: 1 | J3: 2 | K3: 3 | L3: Male | M3: 61 | N3: 2 | O3: 2 | P3: Research Scientist | Q3: 2 | R3: Married | S3: 5130 | T3: 24907 | U3: 1 | V3: Y | W3: No | X3: 23 | Y3: 4 | Z3: 4 | AA3: 80 | AB3: 1 | AC3: 10 | AD3: 3 | AE3: 3 | AF3: 10 | AG3: 7 | AH3: 1 | AI3: 7 | AJ3: {=_xlfn.SWITCH(CleanEmployeeData[[#This Row],[Education]],1,"Below College",2,"College",3,"Bachelor",4,"Master",5,"Doctor","Unknown")} -> Below College | AK3: {=_xlfn.SWITCH(CleanEmployeeData[[#This Row],[EnvironmentSatisfaction]],1,"Low",2,"Medium",3,"High",4,"Very High","Unknown")} -> High | AL3: {=_xlfn.SWITCH(CleanEmployeeData[[#This Row],[JobInvolvement]],1,"Low",2,"Medium",3,"High",4,"Very High","Unknown")} -> Medium | AM3: {=_xlfn.SWITCH(CleanEmployeeData[[#This Row],[JobSatisfaction]],1,"Low",2,"Medium",3,"High",4,"Very High","Unknown")} -> Medium | AN3: {=_xlfn.SWITCH(CleanEmployeeData[[#This Row],[PerformanceRating]],1,"Low",2,"Good",3,"Excellent",4,"Outstanding","Unknown")} -> Outstanding | AO3: {=_xlfn.SWITCH(CleanEmployeeData[[#This Row],[WorkLifeBalance]],1,"Bad",2,"Good",3,"Better",4,"Best","Unknown")} -> Better | AP3: =IF(CleanEmployeeData[[#This Row],[Attrition]]="Yes",1,IF(CleanEmployeeData[[#This Row],[Attrition]]="No",0,"")) -> 0 | AQ3: {=_xlfn.IFS(CleanEmployeeData[[#This Row],[MonthlyIncome]]<=3000,"0–3,000",CleanEmployeeData[[#This Row],[MonthlyIncome]]<=6000,"3,001–6,000",CleanEmployeeData[[#This Row],[MonthlyIncome]]<=10000,"6,001–10,000",TRUE,"10,001+")} -> 3,001–6,000 | AR3: {=_xlfn.IFS(CleanEmployeeData[[#This Row],[DistanceFromHome]]<=5,"0–5 miles",CleanEmployeeData[[#This Row],[DistanceFromHome]]<=10,"6–10 miles",CleanEmployeeData[[#This Row],[DistanceFromHome]]<=15,"11–15 miles",TRUE,"16+ miles")} -> 6–10 miles | AS3: {=_xlfn.IFS(CleanEmployeeData[[#This Row],[YearsAtCompany]]<=1,"0–1 years",CleanEmployeeData[[#This Row],[YearsAtCompany]]<=5,"2–5 years",CleanEmployeeData[[#This Row],[YearsAtCompany]]<=10,"6–10 years",TRUE,"11+ years")} -> 6–10 years
A4: 37 | B4: Yes | C4: Travel_Rarely | D4: 1373 | E4: Research & Development | F4: 2 | G4: 2 | H4: Other | I4: 1 | J4: 4 | K4: 4 | L4: Male | M4: 92 | N4: 2 | O4: 1 | P4: Laboratory Technician | Q4: 3 | R4: Single | S4: 2090 | T4: 2396 | U4: 6 | V4: Y | W4: Yes | X4: 15 | Y4: 3 | Z4: 2 | AA4: 80 | AB4: 0 | AC4: 7 | AD4: 3 | AE4: 3 | AF4: 0 | AG4: 0 | AH4: 0 | AI4: 0 | AJ4: {=_xlfn.SWITCH(CleanEmployeeData[[#This Row],[Education]],1,"Below College",2,"College",3,"Bachelor",4,"Master",5,"Doctor","Unknown")} -> College | AK4: {=_xlfn.SWITCH(CleanEmployeeData[[#This Row],[EnvironmentSatisfaction]],1,"Low",2,"Medium",3,"High",4,"Very High","Unknown")} -> Very High | AL4: {=_xlfn.SWITCH(CleanEmployeeData[[#This Row],[JobInvolvement]],1,"Low",2,"Medium",3,"High",4,"Very High","Unknown")} -> Medium | AM4: {=_xlfn.SWITCH(CleanEmployeeData[[#This Row],[JobSatisfaction]],1,"Low",2,"Medium",3,"High",4,"Very High","Unknown")} -> High | AN4: {=_xlfn.SWITCH(CleanEmployeeData[[#This Row],[PerformanceRating]],1,"Low",2,"Good",3,"Excellent",4,"Outstanding","Unknown")} -> Excellent | AO4: {=_xlfn.SWITCH(CleanEmployeeData[[#This Row],[WorkLifeBalance]],1,"Bad",2,"Good",3,"Better",4,"Best","Unknown")} -> Better | AP4: =IF(CleanEmployeeData[[#This Row],[Attrition]]="Yes",1,IF(CleanEmployeeData[[#This Row],[Attrition]]="No",0,"")) -> 1 | AQ4: {=_xlfn.IFS(CleanEmployeeData[[#This Row],[MonthlyIncome]]<=3000,"0–3,000",CleanEmployeeData[[#This Row],[MonthlyIncome]]<=6000,"3,001–6,000",CleanEmployeeData[[#This Row],[MonthlyIncome]]<=10000,"6,001–10,000",TRUE,"10,001+")} -> 0–3,000 | AR4: {=_xlfn.IFS(CleanEmployeeData[[#This Row],[DistanceFromHome]]<=5,"0–5 miles",CleanEmployeeData[[#This Row],[DistanceFromHome]]<=10,"6–10 miles",CleanEmployeeData[[#This Row],[DistanceFromHome]]<=15,"11–15 miles",TRUE,"16+ miles")} -> 0–5 miles | AS4: {=_xlfn.IFS(CleanEmployeeData[[#This Row],[YearsAtCompany]]<=1,"0–1 years",CleanEmployeeData[[#This Row],[YearsAtCompany]]<=5,"2–5 years",CleanEmployeeData[[#This Row],[YearsAtCompany]]<=10,"6–10 years",TRUE,"11+ years")} -> 0–1 years
A5: 33 | B5: No | C5: Travel_Frequently | D5: 1392 | E5: Research & Development | F5: 3 | G5: 4 | H5: Life Sciences | I5: 1 | J5: 5 | K5: 4 | L5: Female | M5: 56 | N5: 3 | O5: 1 | P5: Research Scientist | Q5: 3 | R5: Married | S5: 2909 | T5: 23159 | U5: 1 | V5: Y | W5: Yes | X5: 11 | Y5: 3 | Z5: 3 | AA5: 80 | AB5: 0 | AC5: 8 | AD5: 3 | AE5: 3 | AF5: 8 | AG5: 7 | AH5: 3 | AI5: 0 | AJ5: {=_xlfn.SWITCH(CleanEmployeeData[[#This Row],[Education]],1,"Below College",2,"College",3,"Bachelor",4,"Master",5,"Doctor","Unknown")} -> Master | AK5: {=_xlfn.SWITCH(CleanEmployeeData[[#This Row],[EnvironmentSatisfaction]],1,"Low",2,"Medium",3,"High",4,"Very High","Unknown")} -> Very High | AL5: {=_xlfn.SWITCH(CleanEmployeeData[[#This Row],[JobInvolvement]],1,"Low",2,"Medium",3,"High",4,"Very High","Unknown")} -> High | AM5: {=_xlfn.SWITCH(CleanEmployeeData[[#This Row],[JobSatisfaction]],1,"Low",2,"Medium",3,"High",4,"Very High","Unknown")} -> High | AN5: {=_xlfn.SWITCH(CleanEmployeeData[[#This Row],[PerformanceRating]],1,"Low",2,"Good",3,"Excellent",4,"Outstanding","Unknown")} -> Excellent | AO5: {=_xlfn.SWITCH(CleanEmployeeData[[#This Row],[WorkLifeBalance]],1,"Bad",2,"Good",3,"Better",4,"Best","Unknown")} -> Better | AP5: =IF(CleanEmployeeData[[#This Row],[Attrition]]="Yes",1,IF(CleanEmployeeData[[#This Row],[Attrition]]="No",0,"")) -> 0 | AQ5: {=_xlfn.IFS(CleanEmployeeData[[#This Row],[MonthlyIncome]]<=3000,"0–3,000",CleanEmployeeData[[#This Row],[MonthlyIncome]]<=6000,"3,001–6,000",CleanEmployeeData[[#This Row],[MonthlyIncome]]<=10000,"6,001–10,000",TRUE,"10,001+")} -> 0–3,000 | AR5: {=_xlfn.IFS(CleanEmployeeData[[#This Row],[DistanceFromHome]]<=5,"0–5 miles",CleanEmployeeData[[#This Row],[DistanceFromHome]]<=10,"6–10 miles",CleanEmployeeData[[#This Row],[DistanceFromHome]]<=15,"11–15 miles",TRUE,"16+ miles")} -> 0–5 miles | AS5: {=_xlfn.IFS(CleanEmployeeData[[#This Row],[YearsAtCompany]]<=1,"0–1 years",CleanEmployeeData[[#This Row],[YearsAtCompany]]<=5,"2–5 years",CleanEmployeeData[[#This Row],[YearsAtCompany]]<=10,"6–10 years",TRUE,"11+ years")} -> 6–10 years
A6: 27 | B6: No | C6: Travel_Rarely | D6: 591 | E6: Research & Development | F6: 2 | G6: 1 | H6: Medical | I6: 1 | J6: 7 | K6: 1 | L6: Male | M6: 40 | N6: 3 | O6: 1 | P6: Laboratory Technician | Q6: 2 | R6: Married | S6: 3468 | T6: 16632 | U6: 9 | V6: Y | W6: No | X6: 12 | Y6: 3 | Z6: 4 | AA6: 80 | AB6: 1 | AC6: 6 | AD6: 3 | AE6: 3 | AF6: 2 | AG6: 2 | AH6: 2 | AI6: 2 | AJ6: {=_xlfn.SWITCH(CleanEmployeeData[[#This Row],[Education]],1,"Below College",2,"College",3,"Bachelor",4,"Master",5,"Doctor","Unknown")} -> Below College | AK6: {=_xlfn.SWITCH(CleanEmployeeData[[#This Row],[EnvironmentSatisfaction]],1,"Low",2,"Medium",3,"High",4,"Very High","Unknown")} -> Low | AL6: {=_xlfn.SWITCH(CleanEmployeeData[[#This Row],[JobInvolvement]],1,"Low",2,"Medium",3,"High",4,"Very High","Unknown")} -> High | AM6: {=_xlfn.SWITCH(CleanEmployeeData[[#This Row],[JobSatisfaction]],1,"Low",2,"Medium",3,"High",4,"Very High","Unknown")} -> Medium | AN6: {=_xlfn.SWITCH(CleanEmployeeData[[#This Row],[PerformanceRating]],1,"Low",2,"Good",3,"Excellent",4,"Outstanding","Unknown")} -> Excellent | AO6: {=_xlfn.SWITCH(CleanEmployeeData[[#This Row],[WorkLifeBalance]],1,"Bad",2,"Good",3,"Better",4,"Best","Unknown")} -> Better | AP6: =IF(CleanEmployeeData[[#This Row],[Attrition]]="Yes",1,IF(CleanEmployeeData[[#This Row],[Attrition]]="No",0,"")) -> 0 | AQ6: {=_xlfn.IFS(CleanEmployeeData[[#This Row],[MonthlyIncome]]<=3000,"0–3,000",CleanEmployeeData[[#This Row],[MonthlyIncome]]<=6000,"3,001–6,000",CleanEmployeeData[[#This Row],[MonthlyIncome]]<=10000,"6,001–10,000",TRUE,"10,001+")} -> 3,001–6,000 | AR6: {=_xlfn.IFS(CleanEmployeeData[[#This Row],[DistanceFromHome]]<=5,"0–5 miles",CleanEmployeeData[[#This Row],[DistanceFromHome]]<=10,"6–10 miles",CleanEmployeeData[[#This Row],[DistanceFromHome]]<=15,"11–15 miles",TRUE,"16+ miles")} -> 0–5 miles | AS6: {=_xlfn.IFS(CleanEmployeeData[[#This Row],[YearsAtCompany]]<=1,"0–1 years",CleanEmployeeData[[#This Row],[YearsAtCompany]]<=5,"2–5 years",CleanEmployeeData[[#This Row],[YearsAtCompany]]<=10,"6–10 years",TRUE,"11+ years")} -> 2–5 years
A7: 32 | B7: No | C7: Travel_Frequently | D7: 1005 | E7: Research & Development | F7: 2 | G7: 2 | H7: Life Sciences | I7: 1 | J7: 8 | K7: 4 | L7: Male | M7: 79 | N7: 3 | O7: 1 | P7: Laboratory Technician | Q7: 4 | R7: Single | S7: 3068 | T7: 11864 | U7: 0 | V7: Y | W7: No | X7: 13 | Y7: 3 | Z7: 3 | AA7: 80 | AB7: 0 | AC7: 8 | AD7: 2 | AE7: 2 | AF7: 7 | AG7: 7 | AH7: 3 | AI7: 6 | AJ7: {=_xlfn.SWITCH(CleanEmployeeData[[#This Row],[Education]],1,"Below College",2,"College",3,"Bachelor",4,"Master",5,"Doctor","Unknown")} -> College | AK7: {=_xlfn.SWITCH(CleanEmployeeData[[#This Row],[EnvironmentSatisfaction]],1,"Low",2,"Medium",3,"High",4,"Very High","Unknown")} -> Very High | AL7: {=_xlfn.SWITCH(CleanEmployeeData[[#This Row],[JobInvolvement]],1,"Low",2,"Medium",3,"High",4,"Very High","Unknown")} -> High | AM7: {=_xlfn.SWITCH(CleanEmployeeData[[#This Row],[JobSatisfaction]],1,"Low",2,"Medium",3,"High",4,"Very High","Unknown")} -> Very High | AN7: {=_xlfn.SWITCH(CleanEmployeeData[[#This Row],[PerformanceRating]],1,"Low",2,"Good",3,"Excellent",4,"Outstanding","Unknown")} -> Excellent | AO7: {=_xlfn.SWITCH(CleanEmployeeData[[#This Row],[WorkLifeBalance]],1,"Bad",2,"Good",3,"Better",4,"Best","Unknown")} -> Good | AP7: =IF(CleanEmployeeData[[#This Row],[Attrition]]="Yes",1,IF(CleanEmployeeData[[#This Row],[Attrition]]="No",0,"")) -> 0 | AQ7: {=_xlfn.IFS(CleanEmployeeData[[#This Row],[MonthlyIncome]]<=3000,"0–3,000",CleanEmployeeData[[#This Row],[MonthlyIncome]]<=6000,"3,001–6,000",CleanEmployeeData[[#This Row],[MonthlyIncome]]<=10000,"6,001–10,000",TRUE,"10,001+")} -> 3,001–6,000 | AR7: {=_xlfn.IFS(CleanEmployeeData[[#This Row],[DistanceFromHome]]<=5,"0–5 miles",CleanEmployeeData[[#This Row],[DistanceFromHome]]<=10,"6–10 miles",CleanEmployeeData[[#This Row],[DistanceFromHome]]<=15,"11–15 miles",TRUE,"16+ miles")} -> 0–5 miles | AS7: {=_xlfn.IFS(CleanEmployeeData[[#This Row],[YearsAtCompany]]<=1,"0–1 years",CleanEmployeeData[[#This Row],[YearsAtCompany]]<=5,"2–5 years",CleanEmployeeData[[#This Row],[YearsAtCompany]]<=10,"6–10 years",TRUE,"11+ years")} -> 6–10 years
A8: 59 | B8: No | C8: Travel_Rarely | D8: 1324 | E8: Research & Development | F8: 3 | G8: 3 | H8: Medical | I8: 1 | J8: 10 | K8: 3 | L8: Female | M8: 81 | N8: 4 | O8: 1 | P8: Laboratory Technician | Q8: 1 | R8: Married | S8: 2670 | T8: 9964 | U8: 4 | V8: Y | W8: Yes | X8: 20 | Y8: 4 | Z8: 1 | AA8: 80 | AB8: 3 | AC8: 12 | AD8: 3 | AE8: 2 | AF8: 1 | AG8: 0 | AH8: 0 | AI8: 0 | AJ8: {=_xlfn.SWITCH(CleanEmployeeData[[#This Row],[Education]],1,"Below College",2,"College",3,"Bachelor",4,"Master",5,"Doctor","Unknown")} -> Bachelor | AK8: {=_xlfn.SWITCH(CleanEmployeeData[[#This Row],[EnvironmentSatisfaction]],1,"Low",2,"Medium",3,"High",4,"Very High","Unknown")} -> High | AL8: {=_xlfn.SWITCH(CleanEmployeeData[[#This Row],[JobInvolvement]],1,"Low",2,"Medium",3,"High",4,"Very High","Unknown")} -> Very High | AM8: {=_xlfn.SWITCH(CleanEmployeeData[[#This Row],[JobSatisfaction]],1,"Low",2,"Medium",3,"High",4,"Very High","Unknown")} -> Low | AN8: {=_xlfn.SWITCH(CleanEmployeeData[[#This Row],[PerformanceRating]],1,"Low",2,"Good",3,"Excellent",4,"Outstanding","Unknown")} -> Outstanding | AO8: {=_xlfn.SWITCH(CleanEmployeeData[[#This Row],[WorkLifeBalance]],1,"Bad",2,"Good",3,"Better",4,"Best","Unknown")} -> Good | AP8: =IF(CleanEmployeeData[[#This Row],[Attrition]]="Yes",1,IF(CleanEmployeeData[[#This Row],[Attrition]]="No",0,"")) -> 0 | AQ8: {=_xlfn.IFS(CleanEmployeeData[[#This Row],[MonthlyIncome]]<=3000,"0–3,000",CleanEmployeeData[[#This Row],[MonthlyIncome]]<=6000,"3,001–6,000",CleanEmployeeData[[#This Row],[MonthlyIncome]]<=10000,"6,001–10,000",TRUE,"10,001+")} -> 0–3,000 | AR8: {=_xlfn.IFS(CleanEmployeeData[[#This Row],[DistanceFromHome]]<=5,"0–5 miles",CleanEmployeeData[[#This Row],[DistanceFromHome]]<=10,"6–10 miles",CleanEmployeeData[[#This Row],[DistanceFromHome]]<=15,"11–15 miles",TRUE,"16+ miles")} -> 0–5 miles | AS8: {=_xlfn.IFS(CleanEmployeeData[[#This Row],[YearsAtCompany]]<=1,"0–1 years",CleanEmployeeData[[#This Row],[YearsAtCompany]]<=5,"2–5 years",CleanEmployeeData[[#This Row],[YearsAtCompany]]<=10,"6–10 years",TRUE,"11+ years")} -> 0–1 years
A9: 30 | B9: No | C9: Travel_Rarely | D9: 1358 | E9: Research & Development | F9: 24 | G9: 1 | H9: Life Sciences | I9: 1 | J9: 11 | K9: 4 | L9: Male | M9: 67 | N9: 3 | O9: 1 | P9: Laboratory Technician | Q9: 3 | R9: Divorced | S9: 2693 | T9: 13335 | U9: 1 | V9: Y | W9: No | X9: 22 | Y9: 4 | Z9: 2 | AA9: 80 | AB9: 1 | AC9: 1 | AD9: 2 | AE9: 3 | AF9: 1 | AG9: 0 | AH9: 0 | AI9: 0 | AJ9: {=_xlfn.SWITCH(CleanEmployeeData[[#This Row],[Education]],1,"Below College",2,"College",3,"Bachelor",4,"Master",5,"Doctor","Unknown")} -> Below College | AK9: {=_xlfn.SWITCH(CleanEmployeeData[[#This Row],[EnvironmentSatisfaction]],1,"Low",2,"Medium",3,"High",4,"Very High","Unknown")} -> Very High | AL9: {=_xlfn.SWITCH(CleanEmployeeData[[#This Row],[JobInvolvement]],1,"Low",2,"Medium",3,"High",4,"Very High","Unknown")} -> High | AM9: {=_xlfn.SWITCH(CleanEmployeeData[[#This Row],[JobSatisfaction]],1,"Low",2,"Medium",3,"High",4,"Very High","Unknown")} -> High | AN9: {=_xlfn.SWITCH(CleanEmployeeData[[#This Row],[PerformanceRating]],1,"Low",2,"Good",3,"Excellent",4,"Outstanding","Unknown")} -> Outstanding | AO9: {=_xlfn.SWITCH(CleanEmployeeData[[#This Row],[WorkLifeBalance]],1,"Bad",2,"Good",3,"Better",4,"Best","Unknown")} -> Better | AP9: =IF(CleanEmployeeData[[#This Row],[Attrition]]="Yes",1,IF(CleanEmployeeData[[#This Row],[Attrition]]="No",0,"")) -> 0 | AQ9: {=_xlfn.IFS(CleanEmployeeData[[#This Row],[MonthlyIncome]]<=3000,"0–3,000",CleanEmployeeData[[#This Row],[MonthlyIncome]]<=6000,"3,001–6,000",CleanEmployeeData[[#This Row],[MonthlyIncome]]<=10000,"6,001–10,000",TRUE,"10,001+")} -> 0–3,000 | AR9: {=_xlfn.IFS(CleanEmployeeData[[#This Row],[DistanceFromHome]]<=5,"0–5 miles",CleanEmployeeData[[#This Row],[DistanceFromHome]]<=10,"6–10 miles",CleanEmployeeData[[#This Row],[DistanceFromHome]]<=15,"11–15 miles",TRUE,"16+ miles")} -> 16+ miles | AS9: {=_xlfn.IFS(CleanEmployeeData[[#This Row],[YearsAtCompany]]<=1,"0–1 years",CleanEmployeeData[[#This Row],[YearsAtCompany]]<=5,"2–5 years",CleanEmployeeData[[#This Row],[YearsAtCompany]]<=10,"6–10 years",TRUE,"11+ years")} -> 0–1 years
A10: 38 | B10: No | C10: Travel_Frequently | D10: 216 | E10: Research & Development | F10: 23 | G10: 3 | H10: Life Sciences | I10: 1 | J10: 12 | K10: 4 | L10: Male | M10: 44 | N10: 2 | O10: 3 | P10: Manufacturing Director | Q10: 3 | R10: Single | S10: 9526 | T10: 8787 | U10: 0 | V10: Y | W10: No | X10: 21 | Y10: 4 | Z10: 2 | AA10: 80 | AB10: 0 | AC10: 10 | AD10: 2 | AE10: 3 | AF10: 9 | AG10: 7 | AH10: 1 | AI10: 8 | AJ10: {=_xlfn.SWITCH(CleanEmployeeData[[#This Row],[Education]],1,"Below College",2,"College",3,"Bachelor",4,"Master",5,"Doctor","Unknown")} -> Bachelor | AK10: {=_xlfn.SWITCH(CleanEmployeeData[[#This Row],[EnvironmentSatisfaction]],1,"Low",2,"Medium",3,"High",4,"Very High","Unknown")} -> Very High | AL10: {=_xlfn.SWITCH(CleanEmployeeData[[#This Row],[JobInvolvement]],1,"Low",2,"Medium",3,"High",4,"Very High","Unknown")} -> Medium | AM10: {=_xlfn.SWITCH(CleanEmployeeData[[#This Row],[JobSatisfaction]],1,"Low",2,"Medium",3,"High",4,"Very High","Unknown")} -> High | AN10: {=_xlfn.SWITCH(CleanEmployeeData[[#This Row],[PerformanceRating]],1,"Low",2,"Good",3,"Excellent",4,"Outstanding","Unknown")} -> Outstanding | AO10: {=_xlfn.SWITCH(CleanEmployeeData[[#This Row],[WorkLifeBalance]],1,"Bad",2,"Good",3,"Better",4,"Best","Unknown")} -> Better | AP10: =IF(CleanEmployeeData[[#This Row],[Attrition]]="Yes",1,IF(CleanEmployeeData[[#This Row],[Attrition]]="No",0,"")) -> 0 | AQ10: {=_xlfn.IFS(CleanEmployeeData[[#This Row],[MonthlyIncome]]<=3000,"0–3,000",CleanEmployeeData[[#This Row],[MonthlyIncome]]<=6000,"3,001–6,000",CleanEmployeeData[[#This Row],[MonthlyIncome]]<=10000,"6,001–10,000",TRUE,"10,001+")} -> 6,001–10,000 | AR10: {=_xlfn.IFS(CleanEmployeeData[[#This Row],[DistanceFromHome]]<=5,"0–5 miles",CleanEmployeeData[[#This Row],[DistanceFromHome]]<=10,"6–10 miles",CleanEmployeeData[[#This Row],[DistanceFromHome]]<=15,"11–15 miles",TRUE,"16+ miles")} -> 16+ miles | AS10: {=_xlfn.IFS(CleanEmployeeData[[#This Row],[YearsAtCompany]]<=1,"0–1 years",CleanEmployeeData[[#This Row],[YearsAtCompany]]<=5,"2–5 years",CleanEmployeeData[[#This Row],[YearsAtCompany]]<=10,"6–10 years",TRUE,"11+ years")} -> 6–10 years
A11: 36 | B11: No | C11: Travel_Rarely | D11: 1299 | E11: Research & Development | F11: 27 | G11: 3 | H11: Medical | I11: 1 | J11: 13 | K11: 3 | L11: Male | M11: 94 | N11: 3 | O11: 2 | P11: Healthcare Representative | Q11: 3 | R11: Married | S11: 5237 | T11: 16577 | U11: 6 | V11: Y | W11: No | X11: 13 | Y11: 3 | Z11: 2 | AA11: 80 | AB11: 2 | AC11: 17 | AD11: 3 | AE11: 2 | AF11: 7 | AG11: 7 | AH11: 7 | AI11: 7 | AJ11: {=_xlfn.SWITCH(CleanEmployeeData[[#This Row],[Education]],1,"Below College",2,"College",3,"Bachelor",4,"Master",5,"Doctor","Unknown")} -> Bachelor | AK11: {=_xlfn.SWITCH(CleanEmployeeData[[#This Row],[EnvironmentSatisfaction]],1,"Low",2,"Medium",3,"High",4,"Very High","Unknown")} -> High | AL11: {=_xlfn.SWITCH(CleanEmployeeData[[#This Row],[JobInvolvement]],1,"Low",2,"Medium",3,"High",4,"Very High","Unknown")} -> High | AM11: {=_xlfn.SWITCH(CleanEmployeeData[[#This Row],[JobSatisfaction]],1,"Low",2,"Medium",3,"High",4,"Very High","Unknown")} -> High | AN11: {=_xlfn.SWITCH(CleanEmployeeData[[#This Row],[PerformanceRating]],1,"Low",2,"Good",3,"Excellent",4,"Outstanding","Unknown")} -> Excellent | AO11: {=_xlfn.SWITCH(CleanEmployeeData[[#This Row],[WorkLifeBalance]],1,"Bad",2,"Good",3,"Better",4,"Best","Unknown")} -> Good | AP11: =IF(CleanEmployeeData[[#This Row],[Attrition]]="Yes",1,IF(CleanEmployeeData[[#This Row],[Attrition]]="No",0,"")) -> 0 | AQ11: {=_xlfn.IFS(CleanEmployeeData[[#This Row],[MonthlyIncome]]<=3000,"0–3,000",CleanEmployeeData[[#This Row],[MonthlyIncome]]<=6000,"3,001–6,000",CleanEmployeeData[[#This Row],[MonthlyIncome]]<=10000,"6,001–10,000",TRUE,"10,001+")} -> 3,001–6,000 | AR11: {=_xlfn.IFS(CleanEmployeeData[[#This Row],[DistanceFromHome]]<=5,"0–5 miles",CleanEmployeeData[[#This Row],[DistanceFromHome]]<=10,"6–10 miles",CleanEmployeeData[[#This Row],[DistanceFromHome]]<=15,"11–15 miles",TRUE,"16+ miles")} -> 16+ miles | AS11: {=_xlfn.IFS(CleanEmployeeData[[#This Row],[YearsAtCompany]]<=1,"0–1 years",CleanEmployeeData[[#This Row],[YearsAtCompany]]<=5,"2–5 years",CleanEmployeeData[[#This Row],[YearsAtCompany]]<=10,"6–10 years",TRUE,"11+ years")} -> 6–10 years
A12: 35 | B12: No | C12: Travel_Rarely | D12: 809 | E12: Research & Development | F12: 16 | G12: 3 | H12: Medical | I12: 1 | J12: 14 | K12: 1 | L12: Male | M12: 84 | N12: 4 | O12: 1 | P12: Laboratory Technician | Q12: 2 | R12: Married | S12: 2426 | T12: 16479 | U12: 0 | V12: Y | W12: No | X12: 13 | Y12: 3 | Z12: 3 | AA12: 80 | AB12: 1 | AC12: 6 | AD12: 5 | AE12: 3 | AF12: 5 | AG12: 4 | AH12: 0 | AI12: 3 | AJ12: {=_xlfn.SWITCH(CleanEmployeeData[[#This Row],[Education]],1,"Below College",2,"College",3,"Bachelor",4,"Master",5,"Doctor","Unknown")} -> Bachelor | AK12: {=_xlfn.SWITCH(CleanEmployeeData[[#This Row],[EnvironmentSatisfaction]],1,"Low",2,"Medium",3,"High",4,"Very High","Unknown")} -> Low | AL12: {=_xlfn.SWITCH(CleanEmployeeData[[#This Row],[JobInvolvement]],1,"Low",2,"Medium",3,"High",4,"Very High","Unknown")} -> Very High | AM12: {=_xlfn.SWITCH(CleanEmployeeData[[#This Row],[JobSatisfaction]],1,"Low",2,"Medium",3,"High",4,"Very High","Unknown")} -> Medium | AN12: {=_xlfn.SWITCH(CleanEmployeeData[[#This Row],[PerformanceRating]],1,"Low",2,"Good",3,"Excellent",4,"Outstanding","Unknown")} -> Excellent | AO12: {=_xlfn.SWITCH(CleanEmployeeData[[#This Row],[WorkLifeBalance]],1,"Bad",2,"Good",3,"Better",4,"Best","Unknown")} -> Better | AP12: =IF(CleanEmployeeData[[#This Row],[Attrition]]="Yes",1,IF(CleanEmployeeData[[#This Row],[Attrition]]="No",0,"")) -> 0 | AQ12: {=_xlfn.IFS(CleanEmployeeData[[#This Row],[MonthlyIncome]]<=3000,"0–3,000",CleanEmployeeData[[#This Row],[MonthlyIncome]]<=6000,"3,001–6,000",CleanEmployeeData[[#This Row],[MonthlyIncome]]<=10000,"6,001–10,000",TRUE,"10,001+")} -> 0–3,000 | AR12: {=_xlfn.IFS(CleanEmployeeData[[#This Row],[DistanceFromHome]]<=5,"0–5 miles",CleanEmployeeData[[#This Row],[DistanceFromHome]]<=10,"6–10 miles",CleanEmployeeData[[#This Row],[DistanceFromHome]]<=15,"11–15 miles",TRUE,"16+ miles")} -> 16+ miles | AS12: {=_xlfn.IFS(CleanEmployeeData[[#This Row],[YearsAtCompany]]<=1,"0–1 years",CleanEmployeeData[[#This Row],[YearsAtCompany]]<=5,"2–5 years",CleanEmployeeData[[#This Row],[YearsAtCompany]]<=10,"6–10 years",TRUE,"11+ years")} -> 2–5 years
A13: 29 | B13: No | C13: Travel_Rarely | D13: 153 | E13: Research & Development | F13: 15 | G13: 2 | H13: Life Sciences | I13: 1 | J13: 15 | K13: 4 | L13: Female | M13: 49 | N13: 2 | O13: 2 | P13: Laboratory Technician | Q13: 3 | R13: Single | S13: 4193 | T13: 12682 | U13: 0 | V13: Y | W13: Yes | X13: 12 | Y13: 3 | Z13: 4 | AA13: 80 | AB13: 0 | AC13: 10 | AD13: 3 | AE13: 3 | AF13: 9 | AG13: 5 | AH13: 0 | AI13: 8 | AJ13: {=_xlfn.SWITCH(CleanEmployeeData[[#This Row],[Education]],1,"Below College",2,"College",3,"Bachelor",4,"Master",5,"Doctor","Unknown")} -> College | AK13: {=_xlfn.SWITCH(CleanEmployeeData[[#This Row],[EnvironmentSatisfaction]],1,"Low",2,"Medium",3,"High",4,"Very High","Unknown")} -> Very High | AL13: {=_xlfn.SWITCH(CleanEmployeeData[[#This Row],[JobInvolvement]],1,"Low",2,"Medium",3,"High",4,"Very High","Unknown")} -> Medium | AM13: {=_xlfn.SWITCH(CleanEmployeeData[[#This Row],[JobSatisfaction]],1,"Low",2,"Medium",3,"High",4,"Very High","Unknown")} -> High | AN13: {=_xlfn.SWITCH(CleanEmployeeData[[#This Row],[PerformanceRating]],1,"Low",2,"Good",3,"Excellent",4,"Outstanding","Unknown")} -> Excellent | AO13: {=_xlfn.SWITCH(CleanEmployeeData[[#This Row],[WorkLifeBalance]],1,"Bad",2,"Good",3,"Better",4,"Best","Unknown")} -> Better | AP13: =IF(CleanEmployeeData[[#This Row],[Attrition]]="Yes",1,IF(CleanEmployeeData[[#This Row],[Attrition]]="No",0,"")) -> 0 | AQ13: {=_xlfn.IFS(CleanEmployeeData[[#This Row],[MonthlyIncome]]<=3000,"0–3,000",CleanEmployeeData[[#This Row],[MonthlyIncome]]<=6000,"3,001–6,000",CleanEmployeeData[[#This Row],[MonthlyIncome]]<=10000,"6,001–10,000",TRUE,"10,001+")} -> 3,001–6,000 | AR13: {=_xlfn.IFS(CleanEmployeeData[[#This Row],[DistanceFromHome]]<=5,"0–5 miles",CleanEmployeeData[[#This Row],[DistanceFromHome]]<=10,"6–10 miles",CleanEmployeeData[[#This Row],[DistanceFromHome]]<=15,"11–15 miles",TRUE,"16+ miles")} -> 11–15 miles | AS13: {=_xlfn.IFS(CleanEmployeeData[[#This Row],[YearsAtCompany]]<=1,"0–1 years",CleanEmployeeData[[#This Row],[YearsAtCompany]]<=5,"2–5 years",CleanEmployeeData[[#This Row],[YearsAtCompany]]<=10,"6–10 years",TRUE,"11+ years")} -> 6–10 years
... A1471: 34 | B1471: No | C1471: Travel_Rarely | D1471: 628 | E1471: Research & Development | F1471: 8 | G1471: 3 | H1471: Medical | I1471: 1 | J1471: 2068 | K1471: 2 | L1471: Male | M1471: 82 | N1471: 4 | O1471: 2 | P1471: Laboratory Technician | Q1471: 3 | R1471: Married | S1471: 4404 | T1471: 10228 | U1471: 2 | V1471: Y | W1471: No | X1471: 12 | Y1471: 3 | Z1471: 1 | AA1471: 80 | AB1471: 0 | AC1471: 6 | AD1471: 3 | AE1471: 4 | AF1471: 4 | AG1471: 3 | AH1471: 1 | AI1471: 2 | AJ1471: {=_xlfn.SWITCH(CleanEmployeeData[[#This Row],[Education]],1,"Below College",2,"College",3,"Bachelor",4,"Master",5,"Doctor","Unknown")} -> Bachelor | AK1471: {=_xlfn.SWITCH(CleanEmployeeData[[#This Row],[EnvironmentSatisfaction]],1,"Low",2,"Medium",3,"High",4,"Very High","Unknown")} -> Medium | AL1471: {=_xlfn.SWITCH(CleanEmployeeData[[#This Row],[JobInvolvement]],1,"Low",2,"Medium",3,"High",4,"Very High","Unknown")} -> Very High | AM1471: {=_xlfn.SWITCH(CleanEmployeeData[[#This Row],[JobSatisfaction]],1,"Low",2,"Medium",3,"High",4,"Very High","Unknown")} -> High | AN1471: {=_xlfn.SWITCH(CleanEmployeeData[[#This Row],[PerformanceRating]],1,"Low",2,"Good",3,"Excellent",4,"Outstanding","Unknown")} -> Excellent | AO1471: {=_xlfn.SWITCH(CleanEmployeeData[[#This Row],[WorkLifeBalance]],1,"Bad",2,"Good",3,"Better",4,"Best","Unknown")} -> Best | AP1471: =IF(CleanEmployeeData[[#This Row],[Attrition]]="Yes",1,IF(CleanEmployeeData[[#This Row],[Attrition]]="No",0,"")) -> 0 | AQ1471: {=_xlfn.IFS(CleanEmployeeData[[#This Row],[MonthlyIncome]]<=3000,"0–3,000",CleanEmployeeData[[#This Row],[MonthlyIncome]]<=6000,"3,001–6,000",CleanEmployeeData[[#This Row],[MonthlyIncome]]<=10000,"6,001–10,000",TRUE,"10,001+")} -> 3,001–6,000 | AR1471: {=_xlfn.IFS(CleanEmployeeData[[#This Row],[DistanceFromHome]]<=5,"0–5 miles",CleanEmployeeData[[#This Row],[DistanceFromHome]]<=10,"6–10 miles",CleanEmployeeData[[#This Row],[DistanceFromHome]]<=15,"11–15 miles",TRUE,"16+ miles")} -> 6–10 miles | AS1471: {=_xlfn.IFS(CleanEmployeeData[[#This Row],[YearsAtCompany]]<=1,"0–1 years",CleanEmployeeData[[#This Row],[YearsAtCompany]]<=5,"2–5 years",CleanEmployeeData[[#This Row],[YearsAtCompany]]<=10,"6–10 years",TRUE,"11+ years")} -> 2–5 years

Sheet Data_Dictionary
A1: Employee Attrition Dataset — Data Dictionary
A3: Column Name | B3: Category / Data Type | C3: Definition | D3: Expected Values / Format | E3: Analytical Handling
A4: Age | B4: Demographic / Whole Number | C4: Employee's age in years | D4: Numeric | E4: Used for age-group and attrition analysis
A5: Attrition | B5: Outcome / Text | C5: Indicates whether the employee left the company | D5: Yes / No | E5: Primary outcome variable
A6: BusinessTravel | B6: Employment / Text | C6: Frequency of business travel | D6: Non-Travel, Travel_Rarely, Travel_Frequently | E6: Used to compare attrition by travel frequency
A7: DailyRate | B7: Compensation / Whole Number | C7: Daily rate value associated with the employee | D7: Numeric | E7: Used for exploratory analysis
A8: Department | B8: Employment / Text | C8: Department where the employee works | D8: Human Resources, Research & Development, Sales | E8: Used for department-level comparisons
A9: DistanceFromHome | B9: Demographic / Whole Number | C9: Distance from home to work, in miles | D9: Numeric | E9: Used to analyze commuting distance and attrition
A10: Education | B10: Demographic / Ordinal Number | C10: Employee's education level | D10: 1–5 | E10: Converted into Education_Label
A11: EducationField | B11: Demographic / Text | C11: Employee's field of education | D11: Life Sciences, Medical, Marketing, Technical Degree, Human Resources, Other | E11: Used to compare attrition by education field
A12: EmployeeCount | B12: Data Quality / Whole Number | C12: Employee count field included in the dataset | D12: Expected constant value: 1 | E12: Checked for variation; not used as a main KPI
A13: EmployeeNumber | B13: Identifier / Whole Number | C13: Unique employee identification number | D13: Numeric identifier | E13: Used for record counts and duplicate checks
A14: EnvironmentSatisfaction | B14: Satisfaction / Ordinal Number | C14: Employee's satisfaction with the work environment | D14: 1–4 | E14: Converted into EnvironmentSatisfaction_Label
... A49: Tenure_Band | B49: Derived / Text | C49: Groups employees by years at the company | D49: 0–1 years; 2–5 years; 6–10 years; 11+ years | E49: Used to compare attrition by company tenure

Sheet Data_Quality
A1: Data Quality Checks
A3: Check | B3: Result | C3: Expected Result | D3: Status
A4: Total Employee Records | B4: =COUNTA(CleanEmployeeData[EmployeeNumber]) -> 1470 | C4: 1470 | D4: =IF(B4=C4,"PASS","REVIEW") -> PASS
A5: Unique Employee Number | B5: =COUNTA(_xlfn.UNIQUE(CleanEmployeeData[EmployeeNumber])) -> 1470 | C5: 1470 | D5: =IF(B5=C5, "PASS", "REVIEW") -> PASS
A6: Missing Value in Raw Data | B6: {=SUMPRODUCT(--(Raw_Data!A2:AI1471=""))} -> 0 | C6: 0 | D6: =IF(B6=C6, "PASS", "REVIEW") -> PASS
A7: Duplicate Employee Numbers | B7: =COUNTA(CleanEmployeeData[EmployeeNumber]) - COUNTA(_xlfn.UNIQUE(CleanEmployeeData[EmployeeNumber])) -> 0 | C7: 0 | D7: =IF(B7=C7, "PASS", "REVIEW") -> PASS
A8: Distinct Employee Count Values | B8: =COUNTA(_xlfn.UNIQUE(CleanEmployeeData[EmployeeCount])) -> 1 | C8: 1 | D8: =IF(B8=C8, "PASS", "REVIEW") -> PASS
A9: Distincty StandardHours Values | B9: =COUNTA((_xlfn.UNIQUE(CleanEmployeeData[StandardHours]))) -> 1 | C9: 1 | D9: =IF(B9=C9, "PASS", "REVIEW") -> PASS

Sheet KPI_Summary
A1: HR Employee Attrition - KPI Summary
A3: Metric | B3: Value
A4: Total Employees | B4: =COUNTA(CleanEmployeeData[EmployeeNumber]) -> 1470
A5: Employees Who Left | B5: =COUNTIF(CleanEmployeeData[Attrition],"Yes") -> 237
A6: Employees Who Stayed | B6: =COUNTIF(CleanEmployeeData[Attrition],"No") -> 1233
A7: Overall Atrrition Rate | B7: =IFERROR(B5/B4,0) -> 0.16122449
A8: Average Monthly Income | B8: =AVERAGE(CleanEmployeeData[MonthlyIncome]) -> 6502.9313
A9: Average Age | B9: =AVERAGE(CleanEmployeeData[Age]) -> 36.92381
A10: Average Years at Company | B10: =AVERAGE(CleanEmployeeData[YearsAtCompany]) -> 7.0081633
A11: Employess Working Overtime | B11: =COUNTIF(CleanEmployeeData[OverTime],"Yes") -> 416
A12: Overtime Attrition Rate | B12: =IFERROR(COUNTIFS(CleanEmployeeData[OverTime],"Yes",CleanEmployeeData[Attrition],"Yes")/COUNTIF(CleanEmployeeData[OverTime],"Yes"),0) -> 0.30528846
A13: Non-Overtime Attrition Rate | B13: =IFERROR(COUNTIFS(CleanEmployeeData[OverTime],"No",CleanEmployeeData[Attrition],"Yes")/COUNTIF(CleanEmployeeData[OverTime],"No"),0) -> 0.10436433
A16: Attrition by department | F16: Attrition by Job Role
A17: Department | B17: Employees | C17: Attrition Count | D17: Attrition Rate | F17: Job Role | G17: Employees | H17: Attrition Count | I17: Attrition Rate
A18: Human Resources | B18: =COUNTIF(CleanEmployeeData[Department],A18) -> 63 | C18: =COUNTIFS(CleanEmployeeData[Department],A18,CleanEmployeeData[Attrition],"Yes") -> 12 | D18: =IFERROR(C18/B18,0) -> 0.19047619 | F18: Healthcare Representative | G18: =COUNTIF(CleanEmployeeData[JobRole],F18) -> 131 | H18: =COUNTIFS(CleanEmployeeData[JobRole],F18,CleanEmployeeData[Attrition],"Yes") -> 9 | I18: =IFERROR(H18/G18,0) -> 0.06870229
A19: Research & Development | B19: =COUNTIF(CleanEmployeeData[Department],A19) -> 961 | C19: =COUNTIFS(CleanEmployeeData[Department],A19,CleanEmployeeData[Attrition],"Yes") -> 133 | D19: =IFERROR(C19/B19,0) -> 0.1383975 | F19: Human Resources | G19: =COUNTIF(CleanEmployeeData[JobRole],F19) -> 52 | H19: =COUNTIFS(CleanEmployeeData[JobRole],F19,CleanEmployeeData[Attrition],"Yes") -> 12 | I19: =IFERROR(H19/G19,0) -> 0.23076923
A20: Sales | B20: =COUNTIF(CleanEmployeeData[Department],A20) -> 446 | C20: =COUNTIFS(CleanEmployeeData[Department],A20,CleanEmployeeData[Attrition],"Yes") -> 92 | D20: =IFERROR(C20/B20,0) -> 0.20627803 | F20: Laboratory Technician | G20: =COUNTIF(CleanEmployeeData[JobRole],F20) -> 259 | H20: =COUNTIFS(CleanEmployeeData[JobRole],F20,CleanEmployeeData[Attrition],"Yes") -> 62 | I20: =IFERROR(H20/G20,0) -> 0.23938224
F21: Manager | G21: =COUNTIF(CleanEmployeeData[JobRole],F21) -> 102 | H21: =COUNTIFS(CleanEmployeeData[JobRole],F21,CleanEmployeeData[Attrition],"Yes") -> 5 | I21: =IFERROR(H21/G21,0) -> 0.049019608
F22: Manufacturing Director | G22: =COUNTIF(CleanEmployeeData[JobRole],F22) -> 145 | H22: =COUNTIFS(CleanEmployeeData[JobRole],F22,CleanEmployeeData[Attrition],"Yes") -> 10 | I22: =IFERROR(H22/G22,0) -> 0.068965517
F23: Research Director | G23: =COUNTIF(CleanEmployeeData[JobRole],F23) -> 80 | H23: =COUNTIFS(CleanEmployeeData[JobRole],F23,CleanEmployeeData[Attrition],"Yes") -> 2 | I23: =IFERROR(H23/G23,0) -> 0.025
F24: Research Scientist | G24: =COUNTIF(CleanEmployeeData[JobRole],F24) -> 292 | H24: =COUNTIFS(CleanEmployeeData[JobRole],F24,CleanEmployeeData[Attrition],"Yes") -> 47 | I24: =IFERROR(H24/G24,0) -> 0.1609589
A25: Attrition by Overtime | F25: Sales Executive | G25: =COUNTIF(CleanEmployeeData[JobRole],F25) -> 326 | H25: =COUNTIFS(CleanEmployeeData[JobRole],F25,CleanEmployeeData[Attrition],"Yes") -> 57 | I25: =IFERROR(H25/G25,0) -> 0.17484663
A26: Overtime | B26: Employees | C26: Attrition Count | D26: Attrition Rate | F26: Sales Representative | G26: =COUNTIF(CleanEmployeeData[JobRole],F26) -> 83 | H26: =COUNTIFS(CleanEmployeeData[JobRole],F26,CleanEmployeeData[Attrition],"Yes") -> 33 | I26: =IFERROR(H26/G26,0) -> 0.39759036
A27: Yes | B27: =COUNTIF(CleanEmployeeData[OverTime],A27) -> 416 | C27: =COUNTIFS(CleanEmployeeData[OverTime],A27,CleanEmployeeData[Attrition],"Yes") -> 127 | D27: =IFERROR(C27/B27,0) -> 0.30528846
A28: No | B28: =COUNTIF(CleanEmployeeData[OverTime],A28) -> 1054 | C28: =COUNTIFS(CleanEmployeeData[OverTime],A28,CleanEmployeeData[Attrition],"Yes") -> 110 | D28: =IFERROR(C28/B28,0) -> 0.10436433
A35: Attrition by Education | F35: Average monthly income by Education and Attrition
A36: Education | B36: Employees | C36: Attrition Count | D36: Attrition Rate | F36: Education | G36: Stayed — Average Income | H36: Left — Average Income
A37: Below College | B37: =COUNTIF(CleanEmployeeData[Education_Label],A37) -> 170 | C37: =COUNTIFS(CleanEmployeeData[Education_Label],A37,CleanEmployeeData[Attrition],"Yes") -> 31 | D37: =IFERROR(C37/B37,0) -> 0.18235294 | F37: Below College | G37: =IFERROR(AVERAGEIFS(CleanEmployeeData[MonthlyIncome],CleanEmployeeData[Education_Label],F37,CleanEmployeeData[Attrition],"No"),0) -> 5926.1295 | H37: =IFERROR(AVERAGEIFS(CleanEmployeeData[MonthlyIncome],CleanEmployeeData[Education_Label],F37,CleanEmployeeData[Attrition],"Yes"),0) -> 4360.1613
A38: College | B38: =COUNTIF(CleanEmployeeData[Education_Label],A38) -> 282 | C38: =COUNTIFS(CleanEmployeeData[Education_Label],A38,CleanEmployeeData[Attrition],"Yes") -> 44 | D38: =IFERROR(C38/B38,0) -> 0.15602837 | F38: College | G38: =IFERROR(AVERAGEIFS(CleanEmployeeData[MonthlyIncome],CleanEmployeeData[Education_Label],F38,CleanEmployeeData[Attrition],"No"),0) -> 6586.0588 | H38: =IFERROR(AVERAGEIFS(CleanEmployeeData[MonthlyIncome],CleanEmployeeData[Education_Label],F38,CleanEmployeeData[Attrition],"Yes"),0) -> 4282.5455
A39: Bachelor | B39: =COUNTIF(CleanEmployeeData[Education_Label],A39) -> 572 | C39: =COUNTIFS(CleanEmployeeData[Education_Label],A39,CleanEmployeeData[Attrition],"Yes") -> 99 | D39: =IFERROR(C39/B39,0) -> 0.17307692 | F39: Bachelor | G39: =IFERROR(AVERAGEIFS(CleanEmployeeData[MonthlyIncome],CleanEmployeeData[Education_Label],F39,CleanEmployeeData[Attrition],"No"),0) -> 6882.9197 | H39: =IFERROR(AVERAGEIFS(CleanEmployeeData[MonthlyIncome],CleanEmployeeData[Education_Label],F39,CleanEmployeeData[Attrition],"Yes"),0) -> 4770.2424
A40: Master | B40: =COUNTIF(CleanEmployeeData[Education_Label],A40) -> 398 | C40: =COUNTIFS(CleanEmployeeData[Education_Label],A40,CleanEmployeeData[Attrition],"Yes") -> 58 | D40: =IFERROR(C40/B40,0) -> 0.14572864 | F40: Master | G40: =IFERROR(AVERAGEIFS(CleanEmployeeData[MonthlyIncome],CleanEmployeeData[Education_Label],F40,CleanEmployeeData[Attrition],"No"),0) -> 7087.8147 | H40: =IFERROR(AVERAGEIFS(CleanEmployeeData[MonthlyIncome],CleanEmployeeData[Education_Label],F40,CleanEmployeeData[Attrition],"Yes"),0) -> 5335.1552
A41: Doctor | B41: =COUNTIF(CleanEmployeeData[Education_Label],A41) -> 48 | C41: =COUNTIFS(CleanEmployeeData[Education_Label],A41,CleanEmployeeData[Attrition],"Yes") -> 5 | D41: =IFERROR(C41/B41,0) -> 0.10416667 | F41: Doctor | G41: =IFERROR(AVERAGEIFS(CleanEmployeeData[MonthlyIncome],CleanEmployeeData[Education_Label],F41,CleanEmployeeData[Attrition],"No"),0) -> 8559.907 | H41: =IFERROR(AVERAGEIFS(CleanEmployeeData[MonthlyIncome],CleanEmployeeData[Education_Label],F41,CleanEmployeeData[Attrition],"Yes"),0) -> 5850.2
A44: Attrition by Work-Life Balance
A45: Work-Life Balance | B45: Employees | C45: Attrition Count | D45: Attrition Rate
A46: Bad | B46: =COUNTIF(CleanEmployeeData[WorkLifeBalance_Label],A46) -> 80 | C46: =COUNTIFS(CleanEmployeeData[WorkLifeBalance_Label],A46,CleanEmployeeData[Attrition],"Yes") -> 25 | D46: =IFERROR(C46/B46,0) -> 0.3125
A47: Good | B47: =COUNTIF(CleanEmployeeData[WorkLifeBalance_Label],A47) -> 344 | C47: =COUNTIFS(CleanEmployeeData[WorkLifeBalance_Label],A47,CleanEmployeeData[Attrition],"Yes") -> 58 | D47: =IFERROR(C47/B47,0) -> 0.16860465
A48: Better | B48: =COUNTIF(CleanEmployeeData[WorkLifeBalance_Label],A48) -> 893 | C48: =COUNTIFS(CleanEmployeeData[WorkLifeBalance_Label],A48,CleanEmployeeData[Attrition],"Yes") -> 127 | D48: =IFERROR(C48/B48,0) -> 0.14221725
A49: Best | B49: =COUNTIF(CleanEmployeeData[WorkLifeBalance_Label],A49) -> 153 | C49: =COUNTIFS(CleanEmployeeData[WorkLifeBalance_Label],A49,CleanEmployeeData[Attrition],"Yes") -> 27 | D49: =IFERROR(C49/B49,0) -> 0.17647059
A52: Attrition by Distance Band
A53: Group | B53: Employees | C53: Attrition Count | D53: Attrition Rate
...

Sheet PivotTables
A13: Attrition by Department & Job Role
B14: Attrition
B15: No | D15: Yes | F15: Total Count of EmployeeNumber | G15: Total Percentage of EmployeeNumber
A16: Department & Job Roles | B16: Count of EmployeeNumber | C16: Percentage of EmployeeNumber | D16: Count of EmployeeNumber | E16: Percentage of EmployeeNumber
A17: Human Resources | B17: 51 | C17: 0.79756888 | D17: 12 | E17: 0.20243112 | F17: 63 | G17: 1
A18: Human Resources | B18: 40 | C18: 0.76090778 | D18: 12 | E18: 0.23909222 | F18: 52 | G18: 1
A19: Manager | B19: 11 | C19: 1 | E19: 0 | F19: 11 | G19: 1
A20: Research & Development | B20: 828 | C20: 0.86940708 | D20: 133 | E20: 0.13059292 | F20: 961 | G20: 1
A21: Healthcare Representative | B21: 122 | C21: 0.93740634 | D21: 9 | E21: 0.062593663 | F21: 131 | G21: 1
A22: Laboratory Technician | B22: 197 | C22: 0.77377286 | D22: 62 | E22: 0.22622714 | F22: 259 | G22: 1
A23: Manager | B23: 51 | C23: 0.96554039 | D23: 3 | E23: 0.034459606 | F23: 54 | G23: 1
A24: Manufacturing Director | B24: 135 | C24: 0.92494131 | D24: 10 | E24: 0.075058694 | F24: 145 | G24: 1
A25: Research Director | B25: 78 | C25: 0.98884862 | D25: 2 | E25: 0.011151384 | F25: 80 | G25: 1
A26: Research Scientist | B26: 245 | C26: 0.84485936 | D26: 47 | E26: 0.15514064 | F26: 292 | G26: 1
A27: Sales | B27: 354 | C27: 0.7890131 | D27: 92 | E27: 0.2109869 | F27: 446 | G27: 1
A28: Manager | B28: 35 | C28: 0.93265063 | D28: 2 | E28: 0.067349373 | F28: 37 | G28: 1
A29: Sales Executive | B29: 269 | C29: 0.81709936 | D29: 57 | E29: 0.18290064 | F29: 326 | G29: 1
A30: Sales Representative | B30: 50 | C30: 0.62036576 | D30: 33 | E30: 0.37963424 | F30: 83 | G30: 1
A31: Grand Total | B31: 1233 | C31: 0.84105959 | D31: 237 | E31: 0.15894041 | F31: 1470 | G31: 1
A36: Distance from home by Job Role & Attrition
B37: Attrition
B38: No | D38: Yes | F38: Total Average of DistanceFromHome | G38: Total Count of EmployeeNumber
A39: Job Role | B39: Average of DistanceFromHome | C39: Count of EmployeeNumber | D39: Average of DistanceFromHome | E39: Count of EmployeeNumber
A40: Healthcare Representative | B40: 9.204918 | C40: 122 | D40: 17.666667 | E40: 9 | F40: 9.7862595 | G40: 131
A41: Human Resources | B41: 6.6 | C41: 40 | D41: 13.416667 | E41: 12 | F41: 8.1730769 | G41: 52
A42: Laboratory Technician | B42: 9.3299492 | C42: 197 | D42: 9.6612903 | E42: 62 | F42: 9.4092664 | G42: 259
A43: Manager | B43: 7.9278351 | C43: 97 | D43: 10 | E43: 5 | F43: 8.0294118 | G43: 102
A44: Manufacturing Director | B44: 9.5333333 | C44: 135 | D44: 8.8 | E44: 10 | F44: 9.4827586 | G44: 145
A45: Research Director | B45: 8.474359 | C45: 78 | D45: 7 | E45: 2 | F45: 8.4375 | G45: 80
A46: Research Scientist | B46: 8.8693878 | C46: 245 | D46: 9.7659574 | E46: 47 | F46: 9.0136986 | G46: 292
A47: Sales Executive | B47: 9.0260223 | C47: 269 | D47: 12.649123 | E47: 57 | F47: 9.6595092 | G47: 326
A48: Sales Representative | B48: 9 | C48: 50 | D48: 8.1515152 | E48: 33 | F48: 8.6626506 | G48: 83
A49: Grand Total | B49: 8.9156529 | C49: 1233 | D49: 10.632911 | E49: 237 | F49: 9.192517 | G49: 1470
A56: Average monthly income by Education & Attrition
A57: Average of MonthlyIncome | B57: Attrition
A58: Education Label | B58: No | C58: Yes | D58: Grand Total
A59: Bachelor | B59: 6882.9197 | C59: 4770.2424 | D59: 6517.264
A60: Below College | B60: 5926.1295 | C60: 4360.1613 | D60: 5640.5706
A61: College | B61: 6586.0588 | C61: 4282.5455 | D61: 6226.6454
A62: Doctor | B62: 8559.907 | C62: 5850.2 | D62: 8277.6458
...

Sheet Analysis_Plan
A1: Employee Attrition Analysis — Business Questions and Excel Methods
A3: Business Question | B3: Objective | C3: Excel Method | D3: Rows / Categories | E3: Columns | F3: Values / Calculation | G3: Recommended Visualization | H3: Analytical Consideration
A4: How many employees are in the dataset? | B4: Establish the size of the workforce represented | C4: COUNTA or PivotTable count | D4: Overall | E4: None | F4: Count of EmployeeNumber | G4: KPI card | H4: Confirms the population covered by the analysis
A5: How many employees left the company? | B5: Quantify employee exits | C5: COUNTIF or PivotTable | D5: Overall | E5: None | F5: Count where Attrition = Yes | G5: KPI card | H5: Shows the number of employees who left
A6: What is the overall attrition rate? | B6: Measure the proportion of employees who left | C6: COUNTIF divided by total employees | D6: Overall | E6: None | F6: Employees with Attrition = Yes ÷ Total employees | G6: KPI card or doughnut chart | H6: Provides the baseline for comparing groups
A7: Which departments have the highest attrition? | B7: Identify departments that may need further investigation | C7: PivotTable with count and row percentages | D7: Department | E7: Attrition | F7: Count of EmployeeNumber and % of row total | G7: Clustered bar chart | H7: Compare rates as well as counts because department sizes differ
A8: Which job roles have the highest attrition? | B8: Identify roles with comparatively high employee exits | C8: PivotTable with count and attrition rate | D8: JobRole | E8: Attrition | F8: Count of EmployeeNumber; calculate attrition rate | G8: Horizontal bar chart | H8: Consider both the number leaving and the proportion leaving
A9: Is attrition different for employees who work overtime? | B9: Explore the relationship between overtime and employee exits | C9: COUNTIFS or PivotTable | D9: OverTime | E9: Attrition | F9: Count of EmployeeNumber; attrition rate by overtime group | G9: Clustered column chart | H9: Compare the rate for Yes against the rate for No
A10: Does distance from home relate to attrition? | B10: Examine whether commuting distance is associated with employee exits | C10: PivotTable or COUNTIFS | D10: Distance_Band | E10: Attrition | F10: Employee count and attrition rate | G10: Column chart | H10: Look for differences across distance bands; do not assume causation
A11: Does monthly income differ between employees who leave and stay? | B11: Compare income across attrition groups | C11: PivotTable | D11: Overall or JobRole | E11: Attrition | F11: Average MonthlyIncome | G11: Clustered bar or column chart | H11: Compare average income while considering job-role and job-level differences
A12: Does education level relate to attrition? | B12: Compare attrition across education categories | C12: PivotTable | D12: Education_Label | E12: Attrition | F12: Employee count and attrition rate | G12: Column chart | H12: Identify differences across education groups
A13: Does job satisfaction relate to attrition? | B13: Explore whether reported satisfaction differs by attrition status | C13: PivotTable | D13: JobSatisfaction_Label | E13: Attrition | F13: Employee count and % of row total | G13: 100% stacked column chart | H13: Compare the attrition share within each satisfaction group
A14: Does work-life balance relate to attrition? | B14: Examine attrition across work-life balance ratings | C14: PivotTable | D14: WorkLifeBalance_Label | E14: Attrition | F14: Employee count and attrition rate | G14: Column chart | H14: Highlight categories with higher observed attrition rates
... A21: Can users explore attrition by different employee groups? | B21: Enable interactive analysis of attrition across employee characteristics | C21: PivotTables, PivotCharts, slicers, and timelines where applicable | D21: Selected employee groups, such as Department, JobRole, Gender, and OverTime | E21: Attrition or selected metric | F21: Employee count, attrition rate, or average income, depending on the selected analysis | G21: Interactive dashboard with KPI cards and PivotCharts | H21: Ensure filters update the relevant visuals consistently and allow users to compare groups
